Workbook

Sheet Synthèse
A1: Recette de vérification — E-Masterclass Big Five
A2: Contrôle du développement au regard de l'e-mail de lancement, des planches A à E de la maquette et des spécifications SEO.
A3: Mise à jour du 15/10 : états relus sur le code, réponses aux retours des testeurs (colonnes K et L, celles du 13/10 reprises du fichier « réponses dev ») et nouvel onglet « Passage en production » pour FeexPay et Zoom. 15/10 après-midi : retest avec captures (colonnes M à O, onglets « Captures » et « En attente client »).
A4: Projet | B4: Plateforme E-Masterclass Big Five — BigFiveAbidjan SARL
A5: Dépôt vérifié | B5: branche recette-marketing-13-10, commit b977ad3 + modifications en cours (masquage de la carte) — relevé initial : main, 79923e2
A6: Date du relevé | B6: 15 octobre 2026 (relevé initial le 2 septembre 2026)
A7: Établi par | B7: Équipe de développement
A8: Contrôles automatiques | B8: 15/10 : npm run build, npm run db:verifier (179/179) et npm run video:verifier (29/29) au vert · npm run typecheck en échec, 5 erreurs de typage (EXP-03)
A10: Comment lire ce classeur
A11: Recette fonctionnelle | B11: les cas à dérouler écran par écran ; renseigner les colonnes « Verdict recette » et « Commentaire »
A12: Points manquants | B12: tout ce qui manque, avec sa conséquence, qui le fournit et si cela bloque l'ouverture
A13: Paiement — FeexPay | B13: le détail des informations d'encaissement à fournir — le poste le plus bloquant
A14: Comptes et clés | B14: les autres comptes prestataires, ce qui est déjà en service et ce qui manque
A15: Conformité SEO | B15: les spécifications SEO point par point, avec l'endroit où c'est implémenté
A16: Couverture e-mail | B16: les 6 points de l'e-mail de lancement, et ce qui en reste ouvert
A17: En attente client | B17: ce qui attend Big Five ou un prestataire, avec la preuve et l'action attendue — et ce qui reste au développement
A18: État du développement — les colonnes chiffrées se recalculent seules
A19: « dont cas critiques » compte les cas dont la criticité est « Bloquant » : ils doivent être au vert avant toute ouverture au public, quel que soit leur état d'avancement.
A20: État | B20: Nombre de cas | C20: dont cas critiques | D20: Ce que cela veut dire
A21: Développé | B21: =COUNTIF('Recette fonctionnelle'!$G:$G,$A21) | C21: =COUNTIFS('Recette fonctionnelle'!$G:$G,$A21,'Recette fonctionnelle'!$H:$H,"Bloquant") | D21: Développé et vérifié sur le dépôt ; reste à dérouler en recette
A22: Développé — échange simulé | B22: =COUNTIF('Recette fonctionnelle'!$G:$G,$A22) | C22: =COUNTIFS('Recette fonctionnelle'!$G:$G,$A22,'Recette fonctionnelle'!$H:$H,"Bloquant") | D22: Le parcours est complet mais l'échange avec le prestataire est simulé
A23: Partiel | B23: =COUNTIF('Recette fonctionnelle'!$G:$G,$A23) | C23: =COUNTIFS('Recette fonctionnelle'!$G:$G,$A23,'Recette fonctionnelle'!$H:$H,"Bloquant") | D23: Une partie de l'écran fonctionne, l'autre attend une donnée ou un accès
A24: À exécuter | B24: =COUNTIF('Recette fonctionnelle'!$G:$G,$A24) | C24: =COUNTIFS('Recette fonctionnelle'!$G:$G,$A24,'Recette fonctionnelle'!$H:$H,"Bloquant") | D24: Le code existe ; un script reste à exécuter sur la base hébergée
A25: Bloqué — prestataire | B25: =COUNTIF('Recette fonctionnelle'!$G:$G,$A25) | C25: =COUNTIFS('Recette fonctionnelle'!$G:$G,$A25,'Recette fonctionnelle'!$H:$H,"Bloquant") | D25: Attend un compte, une clé ou un accès chez un prestataire
A26: Bloqué — contenu client | B26: =COUNTIF('Recette fonctionnelle'!$G:$G,$A26) | C26: =COUNTIFS('Recette fonctionnelle'!$G:$G,$A26,'Recette fonctionnelle'!$H:$H,"Bloquant") | D26: Attend un contenu ou un document du client
A27: Non développé | B27: =COUNTIF('Recette fonctionnelle'!$G:$G,$A27) | C27: =COUNTIFS('Recette fonctionnelle'!$G:$G,$A27,'Recette fonctionnelle'!$H:$H,"Bloquant") | D27: Reste à développer
A28: Total des cas de recette | B28: =SUM(B21:B27) | C28: =SUM(C21:C27)
A30: Avancement de la recette — à mesure que la colonne « Verdict recette » est renseignée
A31: Verdict | B31: Nombre de cas
A32: OK | B32: =COUNTIF('Recette fonctionnelle'!$I:$I,$A32)
A33: KO | B33: =COUNTIF('Recette fonctionnelle'!$I:$I,$A33)
A34: À revoir | B34: =COUNTIF('Recette fonctionnelle'!$I:$I,$A34)
A35: Sans objet | B35: =COUNTIF('Recette fonctionnelle'!$I:$I,$A35)
A36: Non testé | B36: =COUNTIF('Recette fonctionnelle'!$I:$I,$A36)
A38: Ce qui interdit une ouverture au public
A39: • FeexPay — Orange, MTN et Moov ouverts en live, webhook opérationnel (paiement MTN réel du 15/10 refusé par MTN pour solde ou plafond, et tracé). Wave : Clé agrégée Wave à activer (C14). Carte : KYC carte en brouillon (C1) — actions Big Five.
A40: • Envoi d'e-mails — aucun pilote réel : mot de passe oublié, confirmation d'achat, attestation et avis d'annulation ne partent pas.
A41: • Vidéos — 15 chapitres rattachés sur 72 dans la base en ligne.
A42: • Zoom — réglé le 15/10 (app activée, clés posées, mode live) ; reste le test réel de bout en bout (Z6 à Z9).
A43: • Textes juridiques (CGU, CGV, mentions, confidentialité, cookies) et visuels définitifs non fournis.
...

Sheet En attente client
A1: Ce qui attend Big Five ou un prestataire — et ce qui reste au développement
A2: Relevé du 15/10/2026. Partie 1 : points que le développement ne peut pas débloquer seul. Partie 2 : ce qui reste à faire côté code. Chaque preuve renvoie à l'onglet « Captures ».
A4: 1. En attente de Big Five ou d’un prestataire
A5: N° | B5: Blocage | C5: Qui doit agir | D5: Constaté le | E5: Ce que l’on constate | F5: Cas bloqués | G5: Action attendue | H5: Preuve
A6: C1 | B6: Paiement par carte (Visa, Djamo) : KYC carte FeexPay non validé | C6: Big Five (dossier KYC dans le tableau de bord FeexPay) | D6: 15/10/2026 | E6: FeexPay répond 403 CARD_PAYMENT_NOT_AUTHORIZED : « Card payments require a fully validated card KYC », card_kyc_status : draft. Les essais par carte restent « En attente » ; Visa et Djamo sont masqués dans le tunnel en attendant. | F6: ACH-04, ACH-05, ACH-07 | G6: Compléter et soumettre le dossier de conformité carte, puis attendre la validation FeexPay. Prévenir le développement : il vérifie l'activation par l'API, réactive la carte (FEEXPAY_CARTE_ACTIVE=true) et teste Visa et Djamo de bout en bout. | H6: BLQ-KYC → Captures, ligne 155 ADM-20 → Captures, ligne 602
A7: C2 | B7: Zoom : opérationnel depuis le 15/10 | C7: Équipe (test de la salle) | D7: 15/10/2026 | E7: App activée, clés posées, mode réel en production. La session ses-010 a créé sa réunion chez Zoom (83441083225, hôte cossi@). Attention : une session créée depuis un serveur local lancé avant le passage en réel reçoit une réunion fictive — un bandeau le signale désormais. | F7: COL-05, Z7 à Z9 | G7: Tester l'entrée dans la salle (formateur sur ordinateur, apprenant sur mobile), puis reporter et annuler une session réelle. | H7: —
A8: C3 | B8: E-mails : branchés par Resend le 15/10 | C8: Fait (Big Five + dev) | D8: 15/10/2026 | E8: Domaine bigfive.solutions vérifié chez Resend (DKIM, SPF du sous-domaine send) ; réinitialisation délivrée, avis d'annulation envoyé. Deux enregistrements DMARC coexistent sur _dmarc.bigfive.solutions (p=quarantine et p=none). | F8: VIT-17, SEC-07, COL-06 | G8: Garder un seul enregistrement DMARC (supprimer « v=DMARC1; p=none; » dans Cloudflare). Créer la boîte contact@bigfiveabidjan.com si elle n'existe pas. | H8: —
A9: C4 | B9: Domaine de production : branché le 15/10 | C9: Fait | D9: 15/10/2026 | E9: URL définitive https://emasterclass.bigfive.solutions/ : CNAME chez Cloudflare vers Vercel, HTTPS actif, NUXT_PUBLIC_SITE_URL posé. | F9: EXP-05, SEO-10, ATT-06 | G9: Reste à déclarer ce domaine dans la Search Console (C10). | H9: —
A10: C5 | B10: Textes juridiques (CGU, CGV, mentions, confidentialité, cookies) | C10: Big Five (conseil juridique) | D10: 02/09/2026 | E10: Textes provisoires en ligne, y compris les CGV que l’acheteur accepte au récapitulatif. | F10: VIT-20, ACH-03 | G10: Fournir les textes validés. | H10: BLQ-JURIDIQUE → Captures, ligne 127 ACH-03 → Captures, ligne 272
A11: C6 | B11: Vidéos des modules | C11: Big Five (contenus) | D11: 02/09/2026 | E11: 15 chapitres sur 72 ont une vidéo au 15/10. | F11: VID-07 | G11: Livrer les vidéos montées ; elles se déposent dans Admin › Médiathèque vidéo. | H11: BLQ-VIDEOS → Captures, ligne 184
A12: C7 | B12: Modules non publiés et contenus rédactionnels | C12: Big Five (administration) | D12: 15/10/2026 | E12: 15 modules sur 18 sont en « Brouillon » : le catalogue public en montre 3. | F12: VIT-11 | G12: Relire et publier les modules prêts depuis Admin › Modules & chapitres. | H12: BLQ-CATALOGUE → Captures, ligne 4 ADM-06 → Captures, ligne 519
A13: C8 | B13: Griffe de signature de la direction | C13: Big Five (direction) | D13: 02/09/2026 | E13: Le dépôt existe depuis le 21/09 ; la griffe n'est pas déposée. | F13: ATT-05 | G13: Déposer un PNG à fond transparent dans Paramètres › Attestations. | H13: ATT-05 → Captures, ligne 952
A14: C9 | B14: Biographies des formateurs | C14: Big Five (marketing) | D14: 13/10/2026 | E14: Le Google Doc des bios n'est pas partagé avec le développement. | F14: VIT-15 | G14: Saisir les bios dans Admin › Formateurs, ou partager le document. | H14: VIT-15 → Captures, ligne 1377
A15: C10 | B15: GA4, Google Tag Manager, Search Console | C15: Big Five (comptes Google) | D15: 02/09/2026 | E15: Visites et conversion à « — » dans /admin/performances. | F15: ADM-17, ADM-18, SEO-10, SEO-11 | G15: Créer la propriété GA4 et le conteneur GTM, les saisir dans Paramètres › Tracking & pixels ; vérifier le domaine dans la Search Console. | H15: BLQ-GA4 → Captures, ligne 95 ADM-21 → Captures, ligne 711
A16: C11 | B16: WhatsApp Business | C16: Big Five (Meta) | D16: 02/09/2026 | E16: Bouton de contact en place ; aucune notification automatique. | F16: COL-06 | G16: Ouvrir l’accès Meta, vérifier le +225 05 75 15 21 44, faire valider les modèles (1 à 2 semaines). | H16: —
... A19: C13 | B19: Sauvegardes de la base | C19: Big Five (choix de l’offre Supabase) | D19: 02/09/2026 | E19: L'offre gratuite ne garantit ni sauvegarde ni restauration. | F19: EXP-06 | G19: Arbitrer l'offre Supabase. | H19: —
A22: 2. Reste au développement
A23: N° | B23: Blocage | C23: Qui doit agir | D23: Constaté le | E23: Ce que l’on constate | F23: Cas bloqués | G23: Action attendue | H23: Preuve
A24: D1 | B24: /admin/apprenants répondait une erreur 500 | C24: Corrigé (27d835b) | D24: 15/10/2026 | E24: La page s'affiche de nouveau sans erreur (vérifié le 15/10 sur la base en ligne). Cause : une fusion a gardé l'API qui renvoie { apprenants, choix } et repris un écran qui attend une simple liste ; l'écran lit désormais la liste. | F24: ADM-12, ADM-14 | G24: Vérifié le 15/10 : liste des 10 comptes, fiche, historique, export CSV (10 lignes, 13 colonnes), formulaire Prénom / Nom. Reste au testeur : créer un apprenant de test (ADM-12), non rejoué pour ne rien écrire en base. | H24: ADM-12 → Captures, ligne 547 ADM-12-corrige → Captures, ligne 575
A25: D2 | B25: Mots de passe de démonstration encore actifs (dont l'administrateur principal) | C25: Big Five (lancer le script) | D25: 15/10/2026 | E25: Lecture du 15/10 sur la base en ligne : 6 comptes sur 7 acceptent encore le mot de passe commun du jeu de données — cossi@, jeremie.declercq@, houefa@bigfiveabidjan.com, editeur@bigfive.ci, formateur@bigfive.ci, aya@example.ci. Seul jeanluc@ l'a changé. | F25: SEC-11 | G25: Mot de passe retiré du README et du TODO le 15/10. Script prêt : npm run auth:renouveler (lecture seule) puis npm run auth:renouveler -- --appliquer, qui tire un mot de passe aléatoire par compte et l'affiche une seule fois dans le terminal : le reporter dans un gestionnaire, le transmettre à son titulaire. Puis remplacer NUXT_SESSION_PASSWORD sur Vercel pour fermer les sessions ouvertes. | H25: —
A26: D3 | B26: Séance passée affichée « En direct » | C26: Corrigé (27d835b) | D26: 15/10/2026 | E26: La séance du 19/09 affiche « EN DIRECT · 621 h » côté apprenant. | F26: COL-05 | G26: Vérifié le 15/10 : la séance du 19/09 affiche « TERMINÉE · 19 septembre à 20:00 » et « Cette séance s'est terminée », bouton d'entrée grisé, y compris pour le formateur et l'administrateur. | H26: COL-05-seance-passee → Captures, ligne 1136 COL-05-corrige → Captures, ligne 1105
A27: D4 | B27: Rattacher les paiements carte à la commande | C27: Développement (après C1) | D27: 15/10/2026 | E27: Le parcours carte du SDK FeexPay n'envoie pas la référence de commande (custom_id) : une carte débitée risquerait de ne pas ouvrir le module. | F27: ACH-05 | G27: Vérifier sur un vrai paiement carte ; sinon ouvrir la carte depuis le serveur (docs/paiement-carte-a-ajuster.md, §2). | H27: —
A28: D5 | B28: Relance des commandes en attente | C28: Développé (2bc3bcc) | D28: 15/10/2026 | E28: Tâche quotidienne qui relit le statut FeexPay des commandes restées en attente. | F28: ACH-09 | G28: Vérifier après déploiement. | H28: ADM-20 → Captures, ligne 602
A29: D6 | B29: Coaching privé absent de /admin/transactions | C29: Développé (2bc3bcc) | D29: 15/10/2026 | E29: Les paiements de séance deviennent des transactions. | F29: PRI-08 | G29: Exécuter la migration 38 sur la base hébergée avant de déployer. | H29: —
A30: D7 | B30: Contrôle des types | C30: Corrigé (2bc3bcc) | D30: 15/10/2026 | E30: npm run typecheck : 0 erreur. | F30: EXP-03 | G30: — | H30: —
A31: D8 | B31: Droit de lecture de la clé publique sur 2 tables | C31: Développé (2bc3bcc) | D31: 15/10/2026 | E31: Migration 37 : droits retirés sur toutes les tables. | F31: SEC-09 | G31: Exécuter la migration 37 sur la base hébergée. | H31: —
A32: D9 | B32: E-mails de confirmation d'achat et d'attestation | C32: Fusionné dans main | D32: 15/10/2026 | E32: Les deux modèles sont écrits et fusionnés (5b98316, a06e132). | F32: ACH-10, ATT-09 | G32: Déployer, puis vérifier les deux e-mails sur un vrai achat et une vraie délivrance. | H32: —
A35: 3. Corrigé le 15/10 au soir (paiement)
A36: N° | B36: Blocage | C36: Qui doit agir | D36: Constaté le | E36: Ce que l’on constate | F36: Cas bloqués | G36: Action attendue | H36: Preuve
A37: R1 | B37: Description de paiement refusée par FeexPay | C37: Corrigé (123ab6b, 3360135) | D37: 15/10/2026 | E37: FeexPay refuse plus de 40 caractères et les caractères spéciaux : 10 modules sur 18 ne pouvaient pas être payés. | F37: ACH-05 | G37: Description raccourcie et nettoyée. | H37: —
A38: R2 | B38: Page 404 « /achat/undefined » sur Wave | C38: Corrigé (2a2e1b3) | D38: 15/10/2026 | E38: Le SDK ouvrait une adresse vide quand FeexPay refusait Wave. | F38: ACH-04 | G38: Le cadre vide est retiré et un message explicite s’affiche. | H38: —
A39: R3 | B39: Numéro saisi deux fois | C39: Corrigé (e6f4476) | D39: 15/10/2026 | E39: Le SDK ignore le numéro, le nom et l'e-mail transmis. | F39: ACH-04 | G39: La fenêtre FeexPay est pré-remplie, opérateur compris. | H39: ACH-04-prefill → Captures, ligne 378
A40: R4 | B40: Opérateur enregistré « Orange Money » pour un paiement MTN | C40: Corrigé (e6f4476) | D40: 15/10/2026 | E40: FeexPay ne renvoie pas l'opérateur d'un paiement Mobile Money. | F40: ADM-20 | G40: L'opérateur se déduit du numéro payeur (01 Moov, 05 MTN, 07 Orange). | H40: —
A41: R5 | B41: Message d’échec générique | C41: Corrigé (e2706b6, e6f4476) | D41: 15/10/2026 | E41: « Erreur chez le prestataire » au lieu du motif réel. | F41: ACH-06 | G41: Le motif FeexPay est lu, traduit et tracé. | H41: —
A42: R6 | B42: Retour d’Orange Money vers app-v2.feexpay.me | C42: Corrigé (f6126d7) | D42: 15/10/2026 | E42: Le SDK n'envoie pas return_url pour Orange. | F42: ACH-05 | G42: Les adresses de retour du site sont ajoutées à la requête. | H42: —
A43: R7 | B43: Wave et carte invisibles | C43: Corrigé (e6f4476) | D43: 15/10/2026 | E43: Masqués tant que FeexPay ne les ouvrait pas. | F43: ACH-04 | G43: « Bientôt disponible » avec la raison et un renvoi vers le Mobile Money. | H43: ACH-04-wave → Captures, ligne 414 ACH-04-carte → Captures, ligne 340

Sheet Recette fonctionnelle
A1: Recette fonctionnelle
A2: Un cas par ligne. Remplir « Verdict recette » (liste déroulante) et « Commentaire du testeur ». Les autres colonnes décrivent l'état relevé sur le dépôt. « Réponse dev (13/10) » répond aux KO et « À revoir » ; « Mise à jour (15/10) » actualise l'état et donne les contrôles techniques du 15/10. « Retest 15/10 » (colonnes M à O) : cas rejoués le 15/10 après-midi, avec capture dans l'onglet « Captures ».
A4: ID | B4: Domaine | C4: Écran / route | D4: Cas à vérifier | E4: Résultat attendu | F4: Source (maquette / spéc.) | G4: État du développement | H4: Criticité | I4: Verdict recette | J4: Commentaire du testeur | K4: Réponse dev (13/10) | L4: Mise à jour (15/10) | M4: Retest 15/10 | N4: Constat du retest (15/10, avec captures) | O4: Preuve (onglet Captures)
A5: VIT-01 | B5: Site vitrine | C5: / | D5: Carrousel du hero (2 slides) | E5: Un seul H1, partie fixe « Montez en compétences. », sous-titre/CTA/couleur/visuel changent ensemble, pause au survol, navigation clavier, glissement tactile | F5: Planche A · Spéc. SEO §6 | G5: Développé | H5: Majeur | I5: OK
A6: VIT-02 | B6: Site vitrine | C6: / | D6: Bloc des deux programmes | E6: Social Média en violet #80368D, Entrepreneurs en bleu #29358B, lien vers chaque page programme | F6: Planche A | G6: Développé | H6: Majeur | I6: OK
A7: VIT-03 | B7: Site vitrine | C7: / | D7: Accordéon des thématiques | E7: Chaque thématique se déplie et liste ses modules | F7: Planche A | G7: Développé | H7: Mineur | I7: OK
A8: VIT-04 | B8: Site vitrine | C8: / | D8: Section formateurs | E8: Les 3 formateurs avec photo, spécialité et lien vers la fiche | F8: Planche A | G8: Développé | H8: Majeur | I8: OK
A9: VIT-05 | B9: Site vitrine | C9: / | D9: FAQ d'accueil | E9: Questions dépliables, balisage FAQPage | F9: Planche A · Spéc. SEO §9 | G9: Développé | H9: Mineur | I9: OK
A10: VIT-06 | B10: Site vitrine | C10: / | D10: Derniers articles du blog | E10: Les articles publiés remontent ; les brouillons non | F10: Planche A | G10: Développé | H10: Mineur | I10: Non testé
A11: VIT-07 | B11: Site vitrine | C11: Toutes pages | D11: Bouton WhatsApp flottant | E11: Ouvre https://wa.me/2250575152144 avec message pré-rempli | F11: E-mail de lancement §3 | G11: Développé | H11: Majeur | I11: OK
A12: VIT-08 | B12: Site vitrine | C12: /programmes | D12: Liste des deux programmes | E12: Page unique présentant les deux parcours, modules filtrables par thématique | F12: Planche A | G12: Développé | H12: Majeur | I12: OK
A13: VIT-09 | B13: Site vitrine | C13: /programmes/social-media | D13: Page programme Social Média | E13: Hero dégradé + motif de marque, filtres par thématique, FAQ du programme | F13: Planche A | G13: Développé | H13: Majeur | I13: OK
A14: VIT-10 | B14: Site vitrine | C14: /programmes/entrepreneurs | D14: Page programme Entrepreneurs | E14: Idem, en bleu #29358B | F14: Planche A | G14: Développé | H14: Majeur | I14: OK
A15: VIT-11 | B15: Site vitrine | C15: /modules | D15: Catalogue complet | E15: 18 modules, filtres par programme et thématique | F15: Planche A | G15: Développé | H15: Majeur | I15: À revoir | J15: Le catalogue /modules n’est pas accessible via un point d’entrée explicite depuis la landing page. Aucun menu ou CTA “Tous les modules” n’est visible dans la navigation. Sinon sur la page /modules on y retrouve tous les modules, mais on a que 3 modules pas 18 | K15: Corrigé : lien « Modules » dans l'en-tête et le pied de page, bouton « Voir les … modules » sur l'accueil. 3 modules au lieu de 18 : pas un bug d'affichage, les autres modules sont au statut « Brouillon » sur la base en ligne. Les republier depuis Admin › Modules & chapitres. | L15: Corrigé le 13/10 (b977ad3) : entrée « Modules » dans l'en-tête, le pied de page et l'accueil. Les « 3 modules » viennent de la base en ligne : au 15/10, 15 modules sur 18 y sont en brouillon (2 disponibles, 1 en préparation). Les publier depuis /admin/contenus. À retester. | M15: OK | N15: Entrée « Modules » visible dans l'en-tête, le pied de page et l'accueil. Le catalogue n'affiche que 3 modules parce que 15 des 18 sont encore au statut « Brouillon » dans la base en ligne : à publier par l'équipe Big Five (Admin › Modules & chapitres). | O15: VIT-11-accueil → ligne 1321 BLQ-CATALOGUE → ligne 4
A16: VIT-12 | B16: Site vitrine | C16: /modules/[slug] | D16: Fiche module | E16: Promesse, pourquoi, chapitres, formateur, carte d'achat collante à 10 000 FCFA TTC | F16: Planche A | G16: Développé | H16: Bloquant | I16: OK | M16: OK | N16: Fiche module et carte d’achat à 10 000 FCFA TTC. | O16: VIT-12-fiche → ligne 1349
A17: VIT-13 | B17: Site vitrine | C17: /modules/[slug] | D17: Module « en préparation » | E17: Fiche commerciale visible, achat fermé, hors sitemap | F17: Spéc. SEO §5 | G17: Développé | H17: Majeur | I17: OK
A18: VIT-14 | B18: Site vitrine | C18: /formateurs | D18: Liste des formateurs | E18: Profils dépliables, encart coaching privé | F18: Planche A | G18: Développé | H18: Majeur | I18: OK
A19: VIT-15 | B19: Site vitrine | C19: /formateurs/[slug] | D19: Fiche formateur | E19: Biographie, modules animés, données structurées Person | F19: Planche A · Spéc. SEO §9 | G19: Développé | H19: Majeur | I19: À revoir | J19: Mettre à jour les bio https://docs.google.com/document/d/1TwkA0FFDtQUHzaNdNsioVnpKoYeZ6Pda37QqgPBrp1w/edit?tab=t.0 | K19: En attente : le Google Doc n'est pas accessible au développement (accès refusé). Les bios se modifient sans développeur dans Admin › Formateurs (ou par chaque formateur dans son espace). Partager le document ou saisir directement. | L19: Contenu client : reprendre les biographies du Google Doc dans l'administration (Formateurs) ou par chaque formateur dans /formateur/profil. | M19: Bloqué — client | N19: Les biographies affichées sont celles du jeu de données. Le Google Doc des bios n'est pas partagé avec le développement ; les bios se saisissent sans développeur dans Admin › Formateurs. | O19: VIT-15 → ligne 1377
A20: VIT-16 | B20: Site vitrine | C20: /devenir-formateur | D20: Candidature formateur | E20: Le formulaire enregistre la candidature en base et remonte dans /admin/formateurs | F20: Planche E — parcours 06 | G20: Développé | H20: Majeur | I20: OK
A21: VIT-17 | B21: Site vitrine | C21: /contact | D21: Formulaire de contact | E21: La demande part par e-mail vers l'adresse de l'équipe | F21: Planche A | G21: Partiel | H21: Majeur | I21: À revoir | J21: Créer l'adresse mail E-masterclass à partir du nom de domaine | K21: En attente client : adresse e-mail et prestataire d'envoi (point manquant n° 2). Aujourd'hui le message n'est pas envoyé, il est seulement écrit dans le journal du serveur. | L21: Contenu client : créer l'adresse sur le domaine. L'envoi lui-même attend un pilote d'e-mail réel (server/utils/notifications.ts n'écrit qu'en console). | M21: À retester | N21: Envoi branché par Resend depuis le 15/10 : le message part vers contact@bigfiveabidjan.com (CONTACT_DESTINATAIRE), avec un accusé de réception à l'expéditeur. Pas encore essayé en ligne.
A22: VIT-18 | B22: Site vitrine | C22: /sessions | D22: Calendrier public des coachings | E22: Sessions à venir avec thématique, formateur, date et places restantes | F22: Planche A | G22: Développé | H22: Mineur | I22: OK
A23: VIT-19 | B23: Site vitrine | C23: /blog · /blog/[slug] | D23: Section blog | E23: Liste paginée et article complet, balisage Article, partage WhatsApp | F23: E-mail de lancement §5 | G23: Développé | H23: Majeur | I23: OK
A24: VIT-20 | B24: Site vitrine | C24: /mentions-legales · /cgu · /cgv · /confidentialite · /cookies | D24: Pages légales | E24: Textes juridiques validés par le client en ligne | F24: Planche A | G24: Bloqué — contenu client | H24: Bloquant | I24: Non testé | K24: En attente client : textes juridiques validés (point manquant n° 11). | M24: Bloqué — client | N24: Les pages légales portent un texte provisoire (CGV en 4 articles, « dernière mise à jour 1er août »). Textes validés à fournir. | O24: BLQ-JURIDIQUE → ligne 127
A25: VIT-21 | B25: Site vitrine | C25: Toutes pages | D25: Bandeau cookies | E25: 3 catégories (essentiels, audience, marketing), rien n'est chargé avant le choix, re-demande à 1 an, retrait par « Gérer mes cookies » | F25: Planche A — écran 10 | G25: Développé | H25: Bloquant | I25: OK
A26: VIT-22 | B26: Site vitrine | C26: En-tête et pied de page | D26: Numéro WhatsApp affiché | E26: « +225 05 75 15 21 44 » partout, cliquable | F26: E-mail de lancement §3 | G26: Développé | H26: Majeur | I26: OK
A27: VIT-23 | B27: Site vitrine | C27: Toutes pages | D27: Responsive | E27: Points de rupture desktop / tablette / mobile conformes aux planches | F27: Maquette | G27: Développé | H27: Majeur | I27: OK
A28: VIT-24 | B28: Site vitrine | C28: Toutes pages | D28: Typographies | E28: Jost (titres) et Mulish (textes) chargées, auto-hébergées, aucune police tierce restante | F28: E-mail de lancement §6 | G28: Développé | H28: Majeur | I28: OK
A29: VIT-25 | B29: Site vitrine | C29: Fonds sombres | D29: Lisibilité des liens | E29: Contraste suffisant sur barres latérales, hero programme et lecteur | F29: Correctif du 02/09 | G29: Développé | H29: Mineur | I29: OK
A30: ACH-01 | B30: Tunnel d'achat | C30: /modules/[slug] → /achat/compte | D30: Entrée dans le tunnel | E30: Le bouton d'achat mène à l'étape 1 avec le module en mémoire | F30: Planche E — parcours 01 | G30: Développé | H30: Bloquant | I30: OK
A31: ACH-02 | B31: Tunnel d'achat | C31: /achat/compte | D31: Étape 1 — compte | E31: Création de compte ou connexion, puis passage à l'étape 2 | F31: Planche A — écran 04a | G31: Développé | H31: Bloquant | I31: OK
A32: ACH-03 | B32: Tunnel d'achat | C32: /achat/recapitulatif | D32: Étape 2 — récapitulatif | E32: Module, prix TTC, case d'acceptation des CGV | F32: Planche A — écran 04b | G32: Partiel | H32: Bloquant | I32: À revoir | J32: En attente des CGV | K32: En attente client : CGV validées (point manquant n° 11). | L32: Contenu client : CGV à fournir. La case d'acceptation est en place. | M32: Bloqué — client | N32: Récapitulatif et case d'acceptation en place ; les CGV liées sont provisoires. | O32: ACH-03 → ligne 272
A33: ACH-04 | B33: Tunnel d'achat | C33: /achat/paiement | D33: Étape 3 — moyen de paiement | E33: Choix Mobile Money, Wave, Djamo ou Visa | F33: Planche A — écran 04c | G33: Développé | H33: Bloquant | I33: OK | M33: OK | N33: Les quatre moyens sont affichés. Mobile Money (Orange, MTN, Moov) est ouvert ; Wave, Djamo et Visa portent « Bientôt disponible » et expliquent pourquoi (Wave non activé chez FeexPay, KYC carte en brouillon), avec un bouton « Payer par Mobile Money ». La fenêtre FeexPay est pré-remplie : nom, e-mail, numéro et opérateur déduit du numéro (correctifs du 15/10 au soir). | O33: ACH-04 → ligne 306 ACH-04-wave → ligne 414 ACH-04-carte → ligne 340 ACH-04-prefill → ligne 378
A34: ACH-05 | B34: Tunnel d'achat | C34: /achat/paiement | D34: Paiement accepté | E34: Commande + transaction enregistrées, accès au module ouvert immédiatement | F34: Planche E — parcours 01 | G34: Développé | H34: Bloquant | I34: À revoir | J34: Échange simulé mais dans les choix de méthode de paiement, Wave et Djamo se comportent comme le moyen de paiement Mobile Money | K34: Amélioré : chaque moyen a maintenant ses consignes (Wave : QR code ou numéro Wave ; Djamo : carte Djamo ; Visa : 3-D Secure), le numéro est demandé pour Mobile Money et Wave, et l'écran d'attente est adapté. Le paiement reste simulé tant que FeexPay n'est pas branché (point manquant n° 1). | L34: Corrigé le 13/10 (b977ad3) : consignes, numéro et écran d'attente propres à chaque moyen (Mobile Money, Wave, Djamo, Visa). L'échange passe désormais par le widget FeexPay (sandbox en local, live en production). À retester. | M34: OK | N34: Paiement réel validé de bout en bout le 15/10 : Orange Money 200 F à 19:18 (CMD-MV9X8GWL-50A6) et MTN 200 F à 19:25 (CMD-MV9XID99-CFWZ) réussis chez FeexPay, commandes confirmées, modules ouverts dans l'espace de l'acheteur, opérateur bien enregistré. Les refus du payeur (« solde ou plafond ») sont affichés et tracés. Deux défauts corrigés en route : description de plus de 40 caractères refusée par FeexPay, retour d'Orange Money vers app-v2.feexpay.me. | O34: BLQ-FEEXPAY → ligne 66 ADM-20 → ligne 602
A35: ACH-06 | B35: Tunnel d'achat | C35: /achat/paiement | D35: Les 6 motifs d'échec | E35: Solde insuffisant, annulation, délai dépassé, réseau opérateur, carte refusée, erreur inconnue : HTTP 402, message clair, transaction tracée et filtrable | F35: Planche A — écran 04c | G35: Développé | H35: Majeur | I35: À revoir | K35: Recette réelle possible seulement avec le jeu de test FeexPay (onglet Paiement, n° 15). D'ici là, les 6 cas se déroulent en local par le sélecteur « simuler un échec ». | L35: Les motifs viennent désormais de FeexPay (codeEchecDepuisMotif, server/utils/feexpay.ts). Ils se recettent avec le jeu de test du prestataire, ou en production avec un vrai refus (onglet « Passage en production »). | M35: OK | N35: Les motifs viennent de FeexPay et sont explicites : le refus MTN du 15/10 est affiché « Solde insuffisant ou plafond atteint », avec la consigne ; un code FeexPay inconnu est cité tel quel. Au retour d'une page Orange ou Wave en échec : « Paiement annulé ». | O35: BLQ-FEEXPAY → ligne 66
A36: ACH-07 | B36: Tunnel d'achat | C36: server/api/commandes.post.ts | D36: Encaissement réel FeexPay | E36: Appel à l'API FeexPay, redirection de paiement, retour signé vérifié | F36: E-mail de lancement · Planche E | G36: Bloqué — prestataire | H36: Bloquant | I36: Non testé | L36: Développé depuis le 02/09 : modes simulation / sandbox / live ; l'accès ne s'ouvre qu'après lecture du statut chez FeexPay et contrôle du montant. Reste le compte marchand, les clés live et FEEXPAY_MODE=live sur Vercel (onglet « Passage en production »). | M36: Bloqué — prestataire | N36: Encaissement live ouvert pour Orange, MTN et Moov CI. Wave : « Wave aggregated merchant not configured » — la Clé agrégée Wave est à activer dans FeexPay › Configuration. Carte : KYC carte en brouillon (card_kyc_status : draft). | O36: BLQ-FEEXPAY → ligne 66 BLQ-KYC → ligne 155
A37: ACH-08 | B37: Tunnel d'achat | C37: À créer | D37: Webhook / URL de retour FeexPay | E37: Endpoint public qui reçoit et vérifie la notification du prestataire, idempotent | F37: Intégration FeexPay | G37: Partiel | H37: Bloquant | I37: Non testé | L37: Endpoint en place : /api/paiements/feexpay/webhook, idempotent. Il est protégé par une clé (FEEXPAY_WEBHOOK_CLE, en-tête Bearer ou ?cle=) et non par une signature FeexPay ; il ne fait que déclencher une relecture du statut chez FeexPay, ce qui limite le risque. | M37: OK | N37: Webhook opérationnel en production : appelé par FeexPay le 15/10 (HTTP 200, clé Bearer), il a enregistré la transaction MTN « échouée · solde insuffisant ». Il refuse un appel sans clé (401). | O37: BLQ-FEEXPAY → ligne 66
A38: ACH-09 | B38: Tunnel d'achat | C38: /admin/transactions | D38: Rapprochement quotidien | E38: Confrontation des transactions plateforme et du relevé FeexPay | F38: Planche C — écran 18f | G38: Non développé | H38: Majeur | I38: Non testé | L38: Toujours à faire : aucune tâche planifiée ne relit les commandes restées « en attente » (19 dans la base au 15/10). Seule la vérification commande par commande existe. | M38: À retester | N38: Développé le 15/10 : relance quotidienne des commandes restées en attente (cron Vercel 04:00, /api/taches/commandes), qui relit leur statut chez FeexPay. À vérifier après déploiement.
A39: ACH-10 | B39: Tunnel d'achat | C39: Notifications | D39: E-mail de confirmation d'achat | E39: L'apprenant reçoit sa confirmation et sa facture | F39: Planche E — parcours 01 | G39: Bloqué — prestataire | H39: Majeur | I39: Non testé | M39: À retester | N39: Développé le 15/10 (commit 5b98316, fusionné dans main) : e-mail de confirmation d'achat avec module ou séance, montant, moyen et référence, envoyé une seule fois par commande. À retester en ligne après déploiement, avec un vrai paiement.
A40: ACH-11 | B40: Tunnel d'achat | C40: /mon-espace/modules | D40: Accès à vie | E40: Le module acheté reste accessible sans limite de durée | F40: Modèle économique | G40: Développé | H40: Majeur | I40: OK
A41: ACH-12 | B41: Tunnel d'achat | C41: /admin/parametres | D41: Frais de paiement | E41: Taux FeexPay paramétrable (4 % par défaut) et réservé à l'administrateur supérieur | F41: Modèle économique | G41: Développé | H41: Majeur | I41: À revoir | J41: Dans paramètres de l'admin, je ne retrouve pas cette fonction | K41: Le réglage existait mais était introuvable : il est maintenant dans Paramètres › Paramètres financiers (nouveau sous-menu) et sur l'écran Revenus. Modifiable par un administrateur supérieur uniquement (voir ADM-20). | L41: Corrigé le 13/10 : « Paramètres » se déplie dans la barre latérale ; le taux est dans le volet « Paramètres financiers ». Pages réservées aux administrateurs supérieurs : jeanluc@, cossi@, jeremie.declercq@ ou houefa@bigfiveabidjan.com. Le compte admin@bigfive.ci n'existe plus (renommé jeanluc@bigfiveabidjan.com, migration 17) ; editeur@bigfive.ci est administrateur de contenu. À retester. | M41: OK | N41: « Paramètres financiers » accessible depuis le menu Paramètres déplié (compte administrateur supérieur), taux FeexPay à 4 %. | O41: ACH-12 → ligne 452
...

Sheet Points manquants
A1: Points manquants
A2: Tout ce qui n'est pas livré, et pourquoi. « Bloque l'ouverture » = la plateforme ne peut pas être ouverte au public tant que ce point n'est pas réglé.
A4: N° | B4: Catégorie | C4: Ce qui manque | D4: Conséquence aujourd'hui | E4: Bloque l'ouverture | F4: Qui le fournit | G4: Délai à prévoir | H4: Suivi
A5: 1 | B5: Prestataire de paiement | C5: Compte marchand FeexPay et clés live | D5: L'intégration est développée et fonctionne en sandbox ; sans clés live, rien n'est encaissé en production | E5: Oui | F5: Client (compte) | G5: selon FeexPay | H5: Intégration faite — voir « Passage en production »
A6: 2 | B6: Prestataire d'envoi | C6: Compte e-mail transactionnel et authentification DNS du domaine (SPF, DKIM, DMARC) | D6: Un apprenant qui oublie son mot de passe est bloqué ; aucune confirmation d'achat, aucune attestation ni avis d'annulation n'est envoyé | E6: Oui | F6: Client (compte + accès DNS) | G6: 3 à 5 jours
A7: 3 | B7: Prestataire d'envoi | C7: SMTP personnalisé pour Supabase Auth (code à 6 chiffres de /admin/login) | D7: Contourné : le code admin vient d'une application d'authentification (TOTP, migration 23) | E7: Non | F7: Client (compte SMTP) | G7: 1 jour après le compte e-mail | H7: Réglé si CODE_ADMIN_FOURNISSEUR=totp est posé sur Vercel
A8: 4 | B8: Contenu client | C8: Les 18 vidéos montées et validées (72 chapitres) | D8: 2 chapitres de démonstration seulement ; le lecteur affiche « la vidéo n'est pas encore en ligne » partout ailleurs | E8: Oui | F8: Client | G8: à arbitrer — poste le plus long | H8: 15 chapitres rattachés au 15/10
A9: 5 | B9: Contenu client | C9: Transcriptions des chapitres | D9: Le script synchronisé sous le lecteur reste vide | E9: Non | F9: Client | G9: avec les vidéos
A10: 6 | B10: Exploitation | C10: Exécuter 06-video.sql et rattrapage-videos.sql dans SQL Editor | D10: Le lecteur affiche « pas encore en ligne » sur tous les chapitres, y compris les démonstrations | E10: Non | F10: Développement | G10: 2 minutes | H10: Fait — vérifié sur la base en ligne le 15/10
A11: 7 | B11: Prestataire visio | C11: Zoom Pro + app Server-to-Server OAuth + app Meeting SDK (5 clés) | D11: Intégration faite ; la salle reste en simulation tant que les clés ne sont pas posées | E11: Oui | F11: Client | G11: 1 à 2 jours | H11: Voir « Passage en production »
A12: 8 | B12: Prestataire messagerie | C12: WhatsApp Business : accès Meta, vérification du +225 05 75 15 21 44, modèles de message | D12: Aucune notification WhatsApp ; le bouton de contact fonctionne, l'envoi automatique non | E12: Non | F12: Client | G12: 1 à 2 semaines (validation Meta)
A13: 9 | B13: Mesure d'audience | C13: Propriété GA4, conteneur GTM, vérification Search Console | D13: Six indicateurs de /admin/performances affichent « — » et les onglets Funnel, Ventes, Visites, Clients restent incomplets | E13: Non | F13: Client | G13: 1 jour
A14: 10 | B14: Contenu client | C14: Signature de la direction en PNG à fond transparent | D14: L'attestation n'affiche que le trait de signature | E14: Non | F14: Client | G14: immédiat | H14: Dépôt possible depuis l'administration depuis le 21/09
A15: 11 | B15: Contenu client | C15: Textes juridiques validés : CGU, CGV, mentions légales, confidentialité, cookies | D15: Les pages légales et la case du récapitulatif d'achat portent des textes non validés — risque juridique à l'ouverture | E15: Oui | F15: Client (conseil juridique) | G15: 1 à 2 semaines
A16: 12 | B16: Contenu client | C16: Visuels définitifs : photos des formateurs, illustrations des modules et articles, image de partage | D16: Des placeholders rayés s'affichent sur le site public et dans les partages WhatsApp | E16: Oui | F16: Client | G16: 1 à 2 semaines
A17: 13 | B17: Contenu client | C17: Contenu rédactionnel des 16 modules restants (2 validés) | D17: Les fiches suivent le gabarit avec un contenu provisoire | E17: Oui | F17: Client | G17: à arbitrer | H17: 15 modules en brouillon dans la base en ligne au 15/10
A18: 14 | B18: Écart maquette | C18: Titres définitifs de 8 modules (la maquette n'en expose que 10 sur 18) | D18: 8 titres ont été rédigés dans le même registre, à remplacer par ceux du cahier des charges | E18: Non | F18: Client | G18: immédiat
A19: 15 | B19: Écart maquette | C19: Répartition nominative des modules entre les 3 formateurs | D19: La maquette annonce 4 / 3 / 4 modules mais n'en attribue que 10 ; la répartition retenue est cohérente mais reste à valider | E19: Non | F19: Client | G19: immédiat
A20: 16 | B20: Sécurité | C20: Changer les mots de passe des comptes de démonstration | D20: N'apparaît plus à l'écran, mais reste dans le README et sur tous les comptes du jeu de données | E20: Oui | F20: Développement | G20: immédiat
A21: 17 | B21: Sécurité | C21: Double vérification à la connexion apprenant (code 6 chiffres e-mail + WhatsApp) | D21: La table codes_verification existe, l'étape n'est pas activée — prévue par la maquette | E21: Non | F21: Développement (après prestataire d'envoi) | G21: 2 jours
A22: 18 | B22: Développement | C22: Onglets détaillés de Performances (Funnel, Ventes, Visites, Clients) | D22: Les onglets existent mais attendent les données GA4 | E22: Non | F22: Développement (après GA4) | G22: 3 jours
A23: 19 | B23: Développement | C23: Pilote d'envoi réel dans server/utils/notifications.ts | D23: Les points d'appel sont en place ; NOTIFICATIONS_DRIVER n'accepte que « console » | E23: Oui | F23: Développement (après prestataire) | G23: 2 jours
A24: 20 | B24: Développement | C24: Webhook de retour FeexPay, idempotent et signé | D24: Endpoint en place (/api/paiements/feexpay/webhook), protégé par une clé et non par une signature | E24: Non | F24: Développement (après clés) | G24: compris dans l'intégration | H24: Partiel
A25: 21 | B25: Développement | C25: Rapprochement quotidien des transactions avec le relevé FeexPay | D25: Aucune tâche ne relit les commandes en attente (19 en base au 15/10) | E25: Non | F25: Développement | G25: 3 jours
A26: 22 | B26: Développement | C26: Intégration du Zoom Meeting SDK dans /mon-espace/session/[id] | D26: L'écran annonce l'intégration à venir ; le lien de réunion est transmis à la main | E26: Non | F26: Développement (après clés Zoom) | G26: 3 à 5 jours | H26: Fait — reste la configuration
A27: 23 | B27: Développement | C27: Relevé PDF des revenus formateur | D27: Les chiffres sont à l'écran, l'export n'existe pas | E27: Non | F27: Développement | G27: 1 jour | H27: Fait (/formateur/releve/[mois])
A28: 24 | B28: Développement | C28: Export de la liste des apprenants | D28: La liste est consultable, l'export n'existe pas | E28: Non | F28: Développement | G28: 1 jour | H28: Fait (export CSV)
A29: 25 | B29: Développement | C29: Réordonnancement des contenus par glisser-déposer | D29: L'ordre se règle par les positions saisies | E29: Non | F29: Développement | G29: 1 jour | H29: Fait
A30: 26 | B30: Exploitation | C30: Domaine de production, HTTPS et variables d'environnement de production | D30: emasterclass.bigfive.solutions n'est pas encore branché ; NUXT_PUBLIC_SITE_URL pointe vers l'URL Vercel | E30: Oui | F30: Client + développement | G30: 1 jour
A31: 27 | B31: Exploitation | C31: Politique de sauvegarde et de restauration Supabase | D31: L'offre gratuite ne garantit ni sauvegarde ni restauration | E31: Non | F31: Client (arbitrage d'offre) | G31: immédiat
A32: 28 | B32: Recette | C32: Relevé de présence après chaque séance | D32: Sans ce relevé, les taux de présence affichés aux formateurs restent vides | E32: Non | F32: Équipe Big Five (exploitation) | G32: en continu
A33: 29 | B33: Exploitation | C33: Publier les modules prêts : 15 sur 18 sont en brouillon dans la base en ligne | D33: Le catalogue public n'affiche que 3 modules (VIT-11) | E33: Oui | F33: Équipe Big Five (administration) | G33: immédiat | H33: Nouveau (15/10)
A34: 30 | B34: Développement | C34: Erreur de typage sur app/components/admin/Referentiels.vue (EXP-03) | D34: npm run typecheck échoue ; sans effet sur le build | E34: Non | F34: Développement | G34: 1 heure | H34: Nouveau (15/10)
A35: 31 | B35: Sécurité | C35: Retirer le droit de lecture de la clé publique sur visionnages et reglages_attestation | D35: Aucune donnée ne fuit (RLS), mais l'exception tranche avec les 43 autres tables | E35: Non | F35: Développement | G35: immédiat | H35: Nouveau (15/10)
A36: 32 | B36: Développement | C36: Faire apparaître les paiements de coaching privé dans /admin/transactions | D36: Ces paiements ne sont suivis que dans la console FeexPay | E36: Non | F36: Développement | G36: 1 jour | H36: Nouveau (15/10)
A37: 33 | B37: Prestataire de paiement | C37: KYC carte FeexPay à faire valider (Visa, Djamo) | D37: FeexPay refuse la carte (403 CARD_PAYMENT_NOT_AUTHORIZED, card_kyc_status : draft) ; Visa et Djamo sont masqués | E37: Non (Mobile Money et Wave fonctionnent) | F37: Client (tableau de bord FeexPay) | G37: selon FeexPay | H37: Nouveau (15/10) — preuve BLQ-KYC
A38: 34 | B38: Prestataire visio | C38: Activer l'app Zoom Server-to-Server et fournir les identifiants du Meeting SDK | D38: Zoom répond « app disabled by the developer » ; ZOOM_SDK_CLIENT_ID vide | E38: Oui | F38: Client (compte Zoom) | G38: 1 heure | H38: Nouveau (15/10) — preuve BLQ-ZOOM
A39: 35 | B39: Développement | C39: /admin/apprenants en erreur 500 | D39: Création et export d'apprenants indisponibles (ADM-12, ADM-14) | E39: Non | F39: Développement | G39: 1 heure | H39: Nouveau (15/10)
A40: 36 | B40: Sécurité | C40: Mot de passe de démonstration encore actif sur cossi@bigfiveabidjan.com (admin principal) | D40: Le mot de passe est publié dans le README | E40: Oui | F40: Développement + Big Five | G40: immédiat | H40: Nouveau (15/10)
A41: 37 | B41: Développement | C41: Séance passée affichée « EN DIRECT » | D41: La séance du 19/09 affiche « EN DIRECT · 621 h » côté apprenant | E41: Non | F41: Développement | G41: 1 heure | H41: Nouveau (15/10)
...

Sheet Paiement — FeexPay
A1: Paiement — informations FeexPay à fournir
A2: Intégration développée (server/utils/feexpay.ts) : modes simulation, sandbox et live, widget FeexPay dans la page, vérification du statut côté serveur. En local, le mode sandbox est configuré. Reste le compte marchand, les clés live et la bascule de la production — voir l'onglet « Passage en production ».
A4: N° | B4: Information à fournir | C4: Détail attendu | D4: Où elle sera utilisée | E4: Ce qui se passe sans elle | F4: Fournie par | G4: Statut | H4: Date de réception
A5: 1 | B5: Compte marchand FeexPay | C5: Ouverture au nom de BigFiveAbidjan SARL : RCCM, déclaration fiscale d'existence, pièce d'identité du gérant, justificatif d'adresse | D5: Contrat — préalable à toute clé | E5: Rien ne peut être encaissé | F5: Client | G5: À fournir
A6: 2 | B6: Compte de règlement | C6: Coordonnées du compte qui reçoit les reversements : bancaire (RIB) ou Mobile Money marchand | D6: Contrat FeexPay | E6: Les fonds encaissés ne peuvent pas être reversés | F6: Client | G6: À fournir
A7: 3 | B7: Identifiant de boutique (shop / merchant ID) | C7: Chaîne fournie par FeexPay à la création de la boutique | D7: FEEXPAY_SHOP_ID (variable en place) | E7: Aucun appel d'API possible | F7: Client (console FeexPay) | G7: Fourni (test)
A8: 4 | B8: Clé d'API — environnement de test | C8: Token sandbox, à utiliser pendant toute la recette | D8: FEEXPAY_API_KEY avec FEEXPAY_MODE=sandbox — en développement uniquement : un build de production refuse les paiements fictifs du sandbox | E8: Impossible de recetter le paiement sans mouvementer de l'argent réel | F8: Client (console FeexPay) | G8: Fourni
A9: 5 | B9: Clé d'API — production | C9: Token live, transmis séparément et jamais par e-mail en clair | D9: FEEXPAY_API_KEY avec FEEXPAY_MODE=live, posée sur le serveur de production uniquement | E9: Pas de mise en production de l'encaissement | F9: Client (console FeexPay) | G9: À fournir
A10: 6 | B10: Clé du webhook | C10: FeexPay ne signe pas ses notifications : le code attend une clé secrète choisie par nous (32 octets aléatoires), et relit ensuite le statut chez FeexPay | D10: FEEXPAY_WEBHOOK_CLE (et non FEEXPAY_WEBHOOK_SECRET) | E10: Sans clé, le webhook répond 401 à tout appel ; le paiement se confirme alors par le navigateur seul | F10: Développement | G10: Fourni (local) — à régénérer pour la production
A11: 7 | B11: URL de retour (callback / webhook) | C11: À déclarer dans la console FeexPay : https://emasterclass.bigfive.solutions/api/paiements/feexpay/webhook?cle=<FEEXPAY_WEBHOOK_CLE> (ou en-tête Authorization: Bearer <clé>) | D11: Console FeexPay + développement | E11: La plateforme n'apprend jamais qu'un paiement a abouti | F11: Client déclare, développement fournit l'URL | G11: À déclarer après la mise en ligne
A12: 8 | B12: URL de redirection de l'acheteur | C12: Mobile Money et Wave : widget FeexPay, sans quitter /achat/paiement. Carte : page hébergée par FeexPay, retour par callback_url (/achat/paiement?retour=<commande>) et error_callback_url (…&issue=echec). | D12: Console FeexPay | E12: — | F12: Client déclare | G12: En place — à confirmer sur un vrai paiement carte
A13: 9 | B13: Liste blanche d'adresses IP ou de domaines | C13: Si FeexPay la propose : IP sortante du serveur de production et domaine appelant | D13: Console FeexPay | E13: Les appels d'API sont rejetés en production | F13: Client + développement | G13: À vérifier
A14: 10 | B14: Moyens de paiement réellement activés | C14: Confirmer lesquels sont ouverts sur le compte : Orange Money, MTN Money, Moov Money, Wave, Djamo, Visa / Mastercard | D14: Écran /achat/paiement — le tunnel propose aujourd'hui Mobile Money, Wave, Djamo et Visa | E14: Le tunnel proposerait un moyen que le compte refuse | F14: Client | G14: Mobile Money et Wave ouverts ; carte refusée (KYC carte en brouillon, 15/10) : Visa et Djamo masqués
A15: 11 | B15: Taux de commission contractuel | C15: Pourcentage réellement facturé par FeexPay, et s'il diffère selon le moyen de paiement | D15: /admin/parametres — champ « Frais de paiement FeexPay (%) », réglé à 4 % par défaut | E15: Les revenus formateurs (CA − frais, puis 30 / 70) sont calculés sur une hypothèse | F15: Client (contrat) | G15: À confirmer
A16: 12 | B16: Frais fixes éventuels par transaction | C16: Montant fixe s'ajoutant au pourcentage, le cas échéant | D16: Calcul des revenus — server/utils/formateur.ts | E16: Écart entre les revenus affichés et les sommes réellement reçues | F16: Client (contrat) | G16: À confirmer
... A24: 20 | B24: KYC carte (Visa, Djamo) | C24: Dossier de conformité carte de la boutique « Big Five Abidjan » à compléter et faire valider dans le tableau de bord FeexPay | D24: FEEXPAY_CARTE_ACTIVE=true, une fois validé | E24: FeexPay répond 403 CARD_PAYMENT_NOT_AUTHORIZED (card_kyc_status : draft) : aucun paiement par carte possible | F24: Client (tableau de bord FeexPay) | G24: À fournir — bloquant pour la carte
A25: Ce qui est déjà en place côté plateforme
A26: • Le tunnel d'achat complet et le widget FeexPay (Mobile Money, Wave) ; Visa et Djamo masqués tant que le KYC carte n'est pas validé (FEEXPAY_CARTE_ACTIVE).
A27: • La vérification serveur : statut lu chez FeexPay, contrôle de la référence, de la boutique et du montant, puis ouverture des accès — idempotente.
A28: • Le webhook /api/paiements/feexpay/webhook (clé obligatoire) et les motifs d'échec tracés et filtrables dans /admin/transactions.
A29: • Le taux de frais paramétrable dans /admin/parametres (volet Paramètres financiers), utilisé par le calcul des revenus formateurs.
A31: Ce qui reste à faire
A32: • Obtenir le compte marchand et les clés live, puis basculer la production (onglet « Passage en production »).
A33: • Une tâche planifiée qui relit les commandes restées en attente (19 au 15/10) et un suivi des paiements de coaching privé dans /admin/transactions.
A34: • Une procédure de remboursement : rien n'existe dans la plateforme, tout passe par la console FeexPay.
A35: • La recette en production avec un vrai paiement par moyen activé, puis son remboursement.
A36: • Une fois le KYC carte validé : vérifier que la transaction carte porte la référence de commande (custom_id), sinon ouvrir la carte depuis le serveur (docs/paiement-carte-a-ajuster.md).
A37: Transmission des clés : les clés de production ne doivent jamais circuler par e-mail en clair. Les déposer directement dans les variables d'environnement du serveur de production, ou les transmettre par un canal chiffré à usage unique.

Sheet Passage en production
A1: Passage en production — FeexPay et Zoom
A2: Check-list à dérouler une fois le site déployé sur son domaine. Relevée sur le code le 15/10 (server/utils/feexpay.ts, server/utils/zoom.ts). Renseigner « Fait le » au fil de l'eau.
A4: N° | B4: Bloc | C4: Étape | D4: Détail | E4: Où | F4: Qui | G4: Fait le
A5: P1 | B5: Préalable | C5: Domaine et HTTPS | D5: emasterclass.bigfive.solutions pointé sur Vercel, certificat actif. Zoom exige un contexte sécurisé pour la caméra et le micro. | E5: DNS + Vercel > Domains | F5: Client + dev | G5: Fait le 15/10 : https://emasterclass.bigfive.solutions/ (URL définitive)
A6: P2 | B6: Préalable | C6: URL publique du site | D6: NUXT_PUBLIC_SITE_URL=https://emasterclass.bigfive.solutions (sitemap, canonical, QR des attestations). | E6: Vercel > Environment Variables | F6: Dev | G6: Fait le 15/10
A7: P3 | B7: Préalable | C7: Protection des déploiements | D7: Vérifier que la protection SSO de Vercel ne s'applique pas au domaine de production : sinon le webhook FeexPay reçoit une page de connexion. | E7: Vercel > Deployment Protection | F7: Dev | G7: Vérifié le 15/10 (webhook joignable)
A8: P4 | B8: Préalable | C8: Saisie des variables | D8: Sur Vercel, saisir les valeurs sans guillemets (le .env local en contient). Toute variable FEEXPAY_* ou ZOOM_* se pose sous son nom simple, pas en NUXT_… : le mode FeexPay est figé au build. | E8: Vercel > Environment Variables | F8: Dev | G8: Fait le 15/10
A9: F1 | B9: FeexPay — compte | C9: Compte marchand | D9: Ouverture au nom de BigFiveAbidjan SARL (RCCM, DFE, pièce du gérant, justificatif d'adresse) et compte de règlement (RIB ou Mobile Money marchand). | E9: FeexPay | F9: Client
A10: F2 | B10: FeexPay — compte | C10: Moyens de paiement activés | D10: Confirmer Orange, MTN, Moov, Wave, Djamo, Visa/Mastercard. Retirer de l'écran ceux qui ne sont pas ouverts. | E10: Console FeexPay ; app/pages/achat/paiement.vue | F10: Client + dev
A11: F3 | B11: FeexPay — compte | C11: Clés live | D11: Identifiant de boutique et clé API live (fp_…), transmis par canal chiffré, jamais par e-mail en clair. | E11: Console FeexPay | F11: Client
A12: F4 | B12: FeexPay — configuration | C12: Clé du webhook | D12: Générer une nouvelle clé (openssl rand -hex 32), distincte de celle du local. | E12: Poste du développeur | F12: Dev | G12: Fait le 15/10
A13: F5 | B13: FeexPay — configuration | C13: Variables de production | D13: FEEXPAY_MODE=live, FEEXPAY_SHOP_ID, FEEXPAY_API_KEY, FEEXPAY_WEBHOOK_CLE (environnement Production). FEEXPAY_BASE_URL reste par défaut (https://api-v2.feexpay.me). | E13: Vercel > Environment Variables | F13: Dev | G13: Fait le 15/10
A14: F6 | B14: FeexPay — configuration | C14: Redéployer | D14: Relancer un déploiement de production : le chargement du widget dépend du mode lu au build. | E14: Vercel | F14: Dev
A15: F7 | B15: FeexPay — configuration | C15: URL de notification | D15: Déclarer https://emasterclass.bigfive.solutions/api/paiements/feexpay/webhook?cle=<FEEXPAY_WEBHOOK_CLE> (ou en-tête Authorization: Bearer <clé>). Aucune URL de redirection : le paiement se fait dans un widget, sans quitter la page. | E15: Console FeexPay | F15: Client | G15: Fait le 15/10 (en-tête Bearer)
A16: F8 | B16: FeexPay — configuration | C16: Liste blanche | D16: Si FeexPay en exige une : domaine appelant et IP sortantes de Vercel. | E16: Console FeexPay | F16: Client + dev | G16: Sans objet (la liste d’IP ne sert qu’aux reversements)
A17: F9 | B17: FeexPay — configuration | C17: Taux de frais réel | D17: Saisir le taux contractuel dans le volet Paramètres financiers (4 % par défaut). Il sert aux revenus formateurs, pas au montant facturé. | E17: /admin/parametres | F17: Admin supérieur
A18: F10 | B18: FeexPay — recette | C18: Achat réel par moyen activé | D18: Module à petit montant (prix abaissé le temps du test). Vérifier : accès ouvert, transaction « réussie » avec référence FeexPay et réseau. | E18: /achat/paiement ; /admin/transactions | F18: Équipe | G18: Fait le 15/10 : Orange 200 F et MTN 200 F réussis, modules ouverts
A19: F11 | B19: FeexPay — recette | C19: Refus et annulation | D19: Solde insuffisant ou annulation : message clair, transaction « échouée » avec son motif. | E19: /achat/paiement ; /admin/transactions | F19: Équipe | G19: Fait le 15/10 : refus MTN « solde ou plafond » affiché et tracé
A20: F12 | B20: FeexPay — recette | C20: Confirmation par le webhook seul | D20: Fermer l'onglet juste après avoir validé sur le téléphone : la commande doit passer « confirmée » grâce au webhook. | E20: /admin/transactions | F20: Dev | G20: 15/10 : échec MTN reçu et tracé par le webhook
A21: F13 | B21: FeexPay — recette | C21: Coaching privé | D21: Payer une demande confirmée : elle passe « payée ». Ces paiements n'apparaissent pas dans /admin/transactions (contrôle dans la console FeexPay). | E21: /mon-espace/coaching-prive | F21: Équipe
A22: F14 | B22: FeexPay — recette | C22: Remboursement des tests | D22: Rembourser les paiements de test et remettre les prix ; la plateforme n'a pas de procédure de remboursement. | E22: Console FeexPay ; /admin/contenus | F22: Client | G22: À faire : rembourser les 2 paiements de 200 F, remettre les prix
A23: Z1 | B23: Zoom — compte | C23: Licence Zoom Pro | D23: Compte de l'hôte des réunions (2 h, 25 places ; enregistrement cloud si souhaité). | E23: zoom.us | F23: Client
A24: Z2 | B24: Zoom — compte | C24: App Server-to-Server OAuth | D24: Scopes meeting:write:admin et meeting:read:admin ; relever Account ID, Client ID, Client Secret ; activer l'app. Elle crée, déplace et supprime les réunions. | E24: marketplace.zoom.us | F24: Client + dev | G24: Fait le 15/10 (activée)
A25: Z3 | B25: Zoom — compte | C25: App Meeting SDK | D25: Relever SDK Client ID et SDK Secret. Les réunions appartenant à notre propre compte, l'app ne devrait pas avoir à être publiée : à confirmer à la création. | E25: marketplace.zoom.us | F25: Client + dev | G25: Fait le 15/10
A26: Z4 | B26: Zoom — configuration | C26: Variables de production | D26: ZOOM_MODE=live, ZOOM_ACCOUNT_ID, ZOOM_CLIENT_ID, ZOOM_CLIENT_SECRET, ZOOM_SDK_CLIENT_ID, ZOOM_SDK_CLIENT_SECRET (les cinq sont exigées en live). Redéployer. | E26: Vercel > Environment Variables | F26: Dev | G26: Fait le 15/10
A27: Z5 | B27: Zoom — configuration | C27: Sessions créées en simulation | D27: Une session planifiée avant la bascule garde un faux identifiant de réunion : la recréer après. Au 15/10, seule ses-004 (annulée) est concernée. | E27: /admin/sessions | F27: Admin | G27: Fait le 15/10 (ses-008 fictive annulée)
A28: Z6 | B28: Zoom — recette | C28: Création automatique | D28: Créer une session de test : la réunion doit apparaître dans « Réunions à venir » du compte Zoom. | E28: /admin/sessions ; zoom.us | F28: Équipe | G28: Fait le 15/10 : ses-010 → réunion 83441083225 chez Zoom
A29: Z7 | B29: Zoom — recette | C29: Entrée dans la salle | D29: Formateur (hôte) sur ordinateur, apprenant inscrit sur mobile : son, vidéo, partage d'écran, salle d'attente. Un apprenant ne peut entrer que 15 min avant le début. | E29: /mon-espace/session/[id] | F29: Équipe
A30: Z8 | B30: Zoom — recette | C30: Report et annulation | D30: Reporter puis annuler la session de test : la réunion Zoom est déplacée puis supprimée. | E30: /admin/sessions ; zoom.us | F30: Équipe
A31: Z9 | B31: Zoom — recette | C31: Coaching privé | D31: Planifier une demande payée : une réunion est créée. L'événement Google Agenda demande en plus GOOGLE_AGENDA_MODE=live et un compte de service (facultatif). | E31: /admin/coaching-prive | F31: Équipe
A32: Z10 | B32: Zoom — recette | C32: Qualité vidéo | D32: Le site n'envoie pas les en-têtes d'isolation (COOP/COEP) : la galerie vidéo peut être limitée. Si c'est gênant, les ajouter sur /mon-espace/session/** uniquement, pour ne pas casser le widget FeexPay. | E32: nuxt.config.ts (routeRules) | F32: Dev
A34: À savoir : le mode sandbox ne confirme aucun paiement sur un build de production (la référence fictive n'est acceptée qu'en développement). La recette sandbox se fait en local ; la recette de production se fait avec de vrais petits paiements, remboursés ensuite.
A36: Carte bancaire (Visa, Djamo) — après validation du KYC carte
A37: N° | B37: Bloc | C37: Étape | D37: Détail | E37: Où | F37: Qui | G37: Fait le
A38: C1 | B38: Carte — compte | C38: KYC carte | D38: Compléter et soumettre le dossier de conformité carte ; attendre la validation. | E38: Tableau de bord FeexPay | F38: Client
A39: C2 | B39: Carte — contrôle | C39: Vérifier l'activation | D39: POST /api/transactions/public/requesttopay/init (clé live, 100 F) : une payment_url signifie que la carte est ouverte. Ne pas aller au bout de la page. | E39: Poste du développeur | F39: Dev
A40: C3 | B40: Carte — configuration | C40: Réactiver | D40: FEEXPAY_CARTE_ACTIVE=true en Production (et Preview si besoin), puis redéployer : la valeur est lue au build. | E40: Vercel > Environment Variables | F40: Dev
A41: C4 | B41: Carte — recette | C41: Visa et Djamo de bout en bout | D41: Débit, retour sur la plateforme, module ouvert, transaction visible dans /admin/transactions. Vérifier que la transaction porte la référence de commande (custom_id). | E41: /achat/paiement ; /admin/transactions | F41: Équipe + dev
A42: C5 | B42: Carte — questions | C42: À poser à FeexPay | D42: Parcours d’un client Djamo (carte ou autre) ; barème réel des frais carte et qui le paie ; envoi du webhook pour la carte. | E42: Support FeexPay | F42: Client

Sheet Comptes et clés
A1: Comptes prestataires et clés
A2: Ce qui est déjà en service, et ce qui manque. Le détail du paiement est dans l'onglet « Paiement — FeexPay ».
A4: Prestataire / compte | B4: Ce qu'il faut ouvrir ou fournir | C4: Où cela se règle | D4: Statut | E4: Remarque
A5: Supabase (base de données) | B5: Projet hébergé, URL et clé secrète sb_secret_… | C5: SUPABASE_URL, SUPABASE_SECRET_KEY | D5: Fourni — en service | E5: Migrations 01 à 05 appliquées et vérifiées le 02/09
