Workbook

Sheet Synthèse
A1: Recette de vérification — E-Masterclass Big Five
A2: Contrôle du développement au regard de l'e-mail de lancement, des planches A à E de la maquette et des spécifications SEO.
A4: Projet | B4: Plateforme E-Masterclass Big Five — BigFiveAbidjan SARL
A5: Dépôt vérifié | B5: branche main, dernier commit 79923e2
A6: Date du relevé | B6: 2 septembre 2026
A7: Établi par | B7: Équipe de développement
A8: Contrôles automatiques | B8: npm run typecheck : au vert le 02/09 · npm run db:verifier et npm run build : au vert selon le dernier relevé
A10: Comment lire ce classeur
A11: Recette fonctionnelle | B11: les cas à dérouler écran par écran ; renseigner les colonnes « Verdict recette » et « Commentaire »
A12: Points manquants | B12: tout ce qui manque, avec sa conséquence, qui le fournit et si cela bloque l'ouverture
A13: Paiement — FeexPay | B13: le détail des informations d'encaissement à fournir — le poste le plus bloquant
A14: Comptes et clés | B14: les autres comptes prestataires, ce qui est déjà en service et ce qui manque
A15: Conformité SEO | B15: les spécifications SEO point par point, avec l'endroit où c'est implémenté
A16: Couverture e-mail | B16: les 6 points de l'e-mail de lancement, et ce qui en reste ouvert
A18: État du développement — les colonnes chiffrées se recalculent seules
A19: « dont cas critiques » compte les cas dont la criticité est « Bloquant » : ils doivent être au vert avant toute ouverture au public, quel que soit leur état d'avancement.
A20: État | B20: Nombre de cas | C20: dont cas critiques | D20: Ce que cela veut dire
A21: Développé | B21: =COUNTIF('Recette fonctionnelle'!$G:$G,$A21) | C21: =COUNTIFS('Recette fonctionnelle'!$G:$G,$A21,'Recette fonctionnelle'!$H:$H,"Bloquant") | D21: Développé et vérifié sur le dépôt ; reste à dérouler en recette
A22: Développé — échange simulé | B22: =COUNTIF('Recette fonctionnelle'!$G:$G,$A22) | C22: =COUNTIFS('Recette fonctionnelle'!$G:$G,$A22,'Recette fonctionnelle'!$H:$H,"Bloquant") | D22: Le parcours est complet mais l'échange avec le prestataire est simulé
A23: Partiel | B23: =COUNTIF('Recette fonctionnelle'!$G:$G,$A23) | C23: =COUNTIFS('Recette fonctionnelle'!$G:$G,$A23,'Recette fonctionnelle'!$H:$H,"Bloquant") | D23: Une partie de l'écran fonctionne, l'autre attend une donnée ou un accès
A24: À exécuter | B24: =COUNTIF('Recette fonctionnelle'!$G:$G,$A24) | C24: =COUNTIFS('Recette fonctionnelle'!$G:$G,$A24,'Recette fonctionnelle'!$H:$H,"Bloquant") | D24: Le code existe ; un script reste à exécuter sur la base hébergée
A25: Bloqué — prestataire | B25: =COUNTIF('Recette fonctionnelle'!$G:$G,$A25) | C25: =COUNTIFS('Recette fonctionnelle'!$G:$G,$A25,'Recette fonctionnelle'!$H:$H,"Bloquant") | D25: Attend un compte, une clé ou un accès chez un prestataire
A26: Bloqué — contenu client | B26: =COUNTIF('Recette fonctionnelle'!$G:$G,$A26) | C26: =COUNTIFS('Recette fonctionnelle'!$G:$G,$A26,'Recette fonctionnelle'!$H:$H,"Bloquant") | D26: Attend un contenu ou un document du client
A27: Non développé | B27: =COUNTIF('Recette fonctionnelle'!$G:$G,$A27) | C27: =COUNTIFS('Recette fonctionnelle'!$G:$G,$A27,'Recette fonctionnelle'!$H:$H,"Bloquant") | D27: Reste à développer
A28: Total des cas de recette | B28: =SUM(B21:B27) | C28: =SUM(C21:C27)
A30: Avancement de la recette — à mesure que la colonne « Verdict recette » est renseignée
A31: Verdict | B31: Nombre de cas
A32: OK | B32: =COUNTIF('Recette fonctionnelle'!$I:$I,$A32)
A33: KO | B33: =COUNTIF('Recette fonctionnelle'!$I:$I,$A33)
A34: À revoir | B34: =COUNTIF('Recette fonctionnelle'!$I:$I,$A34)
A35: Sans objet | B35: =COUNTIF('Recette fonctionnelle'!$I:$I,$A35)
A36: Non testé | B36: =COUNTIF('Recette fonctionnelle'!$I:$I,$A36)
A38: Ce qui interdit une ouverture au public
A39: • FeexPay — aucune information de paiement fournie : aucune variable FEEXPAY_* n'existe, l'échange avec le prestataire est simulé. Voir l'onglet « Paiement — FeexPay ».
A40: • Envoi d'e-mails — aucun fournisseur : un apprenant qui oublie son mot de passe est bloqué, et le code de la connexion admin s'écrit dans la sortie du serveur.
A41: • Vidéos — 2 chapitres de démonstration sur 72 ; le lecteur affiche son message d'attente partout ailleurs.
A42: • Zoom — Meeting SDK non intégré : la salle de coaching collectif n'existe pas encore dans l'application.
A43: • Textes juridiques et visuels définitifs non fournis.
A44: • Mots de passe des comptes de démonstration à changer, et à retirer de l'écran de connexion et du README.
A45: • Domaine de production, HTTPS et variables d'environnement de production à poser.
...

Sheet Recette fonctionnelle
A1: Recette fonctionnelle
A2: Un cas par ligne. Remplir « Verdict recette » (liste déroulante) et « Commentaire du testeur ». Les autres colonnes décrivent l'état relevé sur le dépôt.
A4: ID | B4: Domaine | C4: Écran / route | D4: Cas à vérifier | E4: Résultat attendu | F4: Source (maquette / spéc.) | G4: État du développement | H4: Criticité | I4: Verdict recette | J4: Commentaire du testeur
A5: VIT-01 | B5: Site vitrine | C5: / | D5: Carrousel du hero (2 slides) | E5: Un seul H1, partie fixe « Montez en compétences. », sous-titre/CTA/couleur/visuel changent ensemble, pause au survol, navigation clavier, glissement tactile | F5: Planche A · Spéc. SEO §6 | G5: Développé | H5: Majeur
A6: VIT-02 | B6: Site vitrine | C6: / | D6: Bloc des deux programmes | E6: Social Média en violet #80368D, Entrepreneurs en bleu #29358B, lien vers chaque page programme | F6: Planche A | G6: Développé | H6: Majeur
A7: VIT-03 | B7: Site vitrine | C7: / | D7: Accordéon des thématiques | E7: Chaque thématique se déplie et liste ses modules | F7: Planche A | G7: Développé | H7: Mineur
A8: VIT-04 | B8: Site vitrine | C8: / | D8: Section formateurs | E8: Les 3 formateurs avec photo, spécialité et lien vers la fiche | F8: Planche A | G8: Bloqué — contenu client | H8: Majeur
A9: VIT-05 | B9: Site vitrine | C9: / | D9: FAQ d'accueil | E9: Questions dépliables, balisage FAQPage | F9: Planche A · Spéc. SEO §9 | G9: Développé | H9: Mineur
A10: VIT-06 | B10: Site vitrine | C10: / | D10: Derniers articles du blog | E10: Les articles publiés remontent ; les brouillons non | F10: Planche A | G10: Développé | H10: Mineur
A11: VIT-07 | B11: Site vitrine | C11: Toutes pages | D11: Bouton WhatsApp flottant | E11: Ouvre https://wa.me/2250575152144 avec message pré-rempli | F11: E-mail de lancement §3 | G11: Développé | H11: Majeur
A12: VIT-08 | B12: Site vitrine | C12: /programmes | D12: Liste des deux programmes | E12: Page unique présentant les deux parcours, modules filtrables par thématique | F12: Planche A | G12: Développé | H12: Majeur
A13: VIT-09 | B13: Site vitrine | C13: /programmes/social-media | D13: Page programme Social Média | E13: Hero dégradé + motif de marque, filtres par thématique, FAQ du programme | F13: Planche A | G13: Développé | H13: Majeur
A14: VIT-10 | B14: Site vitrine | C14: /programmes/entrepreneurs | D14: Page programme Entrepreneurs | E14: Idem, en bleu #29358B | F14: Planche A | G14: Développé | H14: Majeur
A15: VIT-11 | B15: Site vitrine | C15: /modules | D15: Catalogue complet | E15: 18 modules, filtres par programme et thématique | F15: Planche A | G15: Développé | H15: Majeur
A16: VIT-12 | B16: Site vitrine | C16: /modules/[slug] | D16: Fiche module | E16: Promesse, pourquoi, chapitres, formateur, carte d'achat collante à 10 000 FCFA TTC | F16: Planche A | G16: Développé | H16: Bloquant
... A150: EXP-07 | B150: Exploitation | C150: Cloudflare | D150: Diffusion vidéo en service | E150: Bucket R2 créé et Worker déployé — vérifié le 02/09 | F150: TODO §3 | G150: Développé | H150: Majeur

Sheet Points manquants
A1: Points manquants
A2: Tout ce qui n'est pas livré, et pourquoi. « Bloque l'ouverture » = la plateforme ne peut pas être ouverte au public tant que ce point n'est pas réglé.
A4: N° | B4: Catégorie | C4: Ce qui manque | D4: Conséquence aujourd'hui | E4: Bloque l'ouverture | F4: Qui le fournit | G4: Délai à prévoir | H4: Suivi
A5: 1 | B5: Prestataire de paiement | C5: Intégration FeexPay complète : compte marchand, clés, appel d'API et retour signé | D5: Aucun argent n'est encaissé : la commande s'enregistre et l'accès s'ouvre, l'échange avec le prestataire est simulé | E5: Oui | F5: Client (compte) + développement | G5: 2 à 3 semaines
A6: 2 | B6: Prestataire d'envoi | C6: Compte e-mail transactionnel et authentification DNS du domaine (SPF, DKIM, DMARC) | D6: Un apprenant qui oublie son mot de passe est bloqué ; aucune confirmation d'achat, aucune attestation ni avis d'annulation n'est envoyé | E6: Oui | F6: Client (compte + accès DNS) | G6: 3 à 5 jours
A7: 3 | B7: Prestataire d'envoi | C7: SMTP personnalisé pour Supabase Auth (code à 6 chiffres de /admin/login) | D7: Sur l'offre gratuite, Supabase refuse le gabarit avec code : le code s'écrit dans la sortie du serveur, la connexion admin n'est pas utilisable en production | E7: Oui | F7: Client (compte SMTP) | G7: 1 jour après le compte e-mail
A8: 4 | B8: Contenu client | C8: Les 18 vidéos montées et validées (72 chapitres) | D8: 2 chapitres de démonstration seulement ; le lecteur affiche « la vidéo n'est pas encore en ligne » partout ailleurs | E8: Oui | F8: Client | G8: à arbitrer — poste le plus long
A9: 5 | B9: Contenu client | C9: Transcriptions des chapitres | D9: Le script synchronisé sous le lecteur reste vide | E9: Non | F9: Client | G9: avec les vidéos
A10: 6 | B10: Exploitation | C10: Exécuter 06-video.sql et rattrapage-videos.sql dans SQL Editor | D10: Le lecteur affiche « pas encore en ligne » sur tous les chapitres, y compris les démonstrations | E10: Oui | F10: Développement | G10: 2 minutes
A11: 7 | B11: Prestataire visio | C11: Zoom Pro + application Meeting SDK (SDK Key et SDK Secret) | D11: La salle de coaching collectif n'est pas intégrée ; l'équipe crée la réunion à la main et transmet le lien | E11: Oui | F11: Client | G11: 1 à 2 jours
A12: 8 | B12: Prestataire messagerie | C12: WhatsApp Business : accès Meta, vérification du +225 05 75 15 21 44, modèles de message | D12: Aucune notification WhatsApp ; le bouton de contact fonctionne, l'envoi automatique non | E12: Non | F12: Client | G12: 1 à 2 semaines (validation Meta)
A13: 9 | B13: Mesure d'audience | C13: Propriété GA4, conteneur GTM, vérification Search Console | D13: Six indicateurs de /admin/performances affichent « — » et les onglets Funnel, Ventes, Visites, Clients restent incomplets | E13: Non | F13: Client | G13: 1 jour
A14: 10 | B14: Contenu client | C14: Signature de la direction en PNG à fond transparent | D14: L'attestation n'affiche que le trait de signature | E14: Non | F14: Client | G14: immédiat
A15: 11 | B15: Contenu client | C15: Textes juridiques validés : CGU, CGV, mentions légales, confidentialité, cookies | D15: Les pages légales et la case du récapitulatif d'achat portent des textes non validés — risque juridique à l'ouverture | E15: Oui | F15: Client (conseil juridique) | G15: 1 à 2 semaines
A16: 12 | B16: Contenu client | C16: Visuels définitifs : photos des formateurs, illustrations des modules et articles, image de partage | D16: Des placeholders rayés s'affichent sur le site public et dans les partages WhatsApp | E16: Oui | F16: Client | G16: 1 à 2 semaines
... A32: 28 | B32: Recette | C32: Relevé de présence après chaque séance | D32: Sans ce relevé, les taux de présence affichés aux formateurs restent vides | E32: Non | F32: Équipe Big Five (exploitation) | G32: en continu
A34: Total des points manquants : 28, dont 14 bloquent l'ouverture au public.

Sheet Paiement — FeexPay
A1: Paiement — informations FeexPay à fournir
A2: Poste le plus bloquant du projet. À ce jour aucune information de paiement n'a été transmise : aucune variable FEEXPAY_* n'existe dans la configuration, et l'échange avec le prestataire est simulé dans server/api/commandes.post.ts.
A4: N° | B4: Information à fournir | C4: Détail attendu | D4: Où elle sera utilisée | E4: Ce qui se passe sans elle | F4: Fournie par | G4: Statut | H4: Date de réception
A5: 1 | B5: Compte marchand FeexPay | C5: Ouverture au nom de BigFiveAbidjan SARL : RCCM, déclaration fiscale d'existence, pièce d'identité du gérant, justificatif d'adresse | D5: Contrat — préalable à toute clé | E5: Rien ne peut être encaissé | F5: Client | G5: À fournir
A6: 2 | B6: Compte de règlement | C6: Coordonnées du compte qui reçoit les reversements : bancaire (RIB) ou Mobile Money marchand | D6: Contrat FeexPay | E6: Les fonds encaissés ne peuvent pas être reversés | F6: Client | G6: À fournir
A7: 3 | B7: Identifiant de boutique (shop / merchant ID) | C7: Chaîne fournie par FeexPay à la création de la boutique | D7: Variable d'environnement à créer : FEEXPAY_SHOP_ID | E7: Aucun appel d'API possible | F7: Client (console FeexPay) | G7: À fournir
A8: 4 | B8: Clé d'API — environnement de test | C8: Token sandbox, à utiliser pendant toute la recette | D8: FEEXPAY_API_KEY avec FEEXPAY_MODE=sandbox | E8: Impossible de recetter le paiement sans mouvementer de l'argent réel | F8: Client (console FeexPay) | G8: À fournir
A9: 5 | B9: Clé d'API — production | C9: Token live, transmis séparément et jamais par e-mail en clair | D9: FEEXPAY_API_KEY avec FEEXPAY_MODE=live, posée sur le serveur de production uniquement | E9: Pas de mise en production de l'encaissement | F9: Client (console FeexPay) | G9: À fournir
A10: 6 | B10: Clé de signature du retour (webhook secret) | C10: Secret partagé permettant de vérifier que la notification vient bien de FeexPay | D10: FEEXPAY_WEBHOOK_SECRET | E10: Un tiers pourrait déclarer un paiement réussi : faille d'accès gratuit aux modules | F10: Client (console FeexPay) | G10: À fournir
A11: 7 | B11: URL de retour (callback / webhook) | C11: À déclarer dans la console FeexPay : https://emasterclass.bigfive.ci/api/paiements/feexpay/retour (endpoint à créer) | D11: Console FeexPay + développement | E11: La plateforme n'apprend jamais qu'un paiement a abouti | F11: Client déclare, développement fournit l'URL | G11: À déclarer
A12: 8 | B12: URL de redirection de l'acheteur | C12: Pages de retour succès et échec : /achat/paiement (succès et échec déjà gérés côté écran) | D12: Console FeexPay | E12: L'acheteur reste bloqué sur la page du prestataire | F12: Client déclare | G12: À déclarer
A13: 9 | B13: Liste blanche d'adresses IP ou de domaines | C13: Si FeexPay la propose : IP sortante du serveur de production et domaine appelant | D13: Console FeexPay | E13: Les appels d'API sont rejetés en production | F13: Client + développement | G13: À vérifier
A14: 10 | B14: Moyens de paiement réellement activés | C14: Confirmer lesquels sont ouverts sur le compte : Orange Money, MTN Money, Moov Money, Wave, Djamo, Visa / Mastercard | D14: Écran /achat/paiement — le tunnel propose aujourd'hui Mobile Money, Wave, Djamo et Visa | E14: Le tunnel proposerait un moyen que le compte refuse | F14: Client | G14: À confirmer
A15: 11 | B15: Taux de commission contractuel | C15: Pourcentage réellement facturé par FeexPay, et s'il diffère selon le moyen de paiement | D15: /admin/parametres — champ « Frais de paiement FeexPay (%) », réglé à 4 % par défaut | E15: Les revenus formateurs (CA − frais, puis 30 / 70) sont calculés sur une hypothèse | F15: Client (contrat) | G15: À confirmer
A16: 12 | B16: Frais fixes éventuels par transaction | C16: Montant fixe s'ajoutant au pourcentage, le cas échéant | D16: Calcul des revenus — server/utils/formateur.ts | E16: Écart entre les revenus affichés et les sommes réellement reçues | F16: Client (contrat) | G16: À confirmer
... A23: 19 | B23: Facture et mentions légales de vente | C23: Modèle de facture, mentions TVA, conditions de vente à afficher au récapitulatif | D23: /achat/recapitulatif et CGV | E23: Vente en ligne sans document comptable conforme | F23: Client | G23: À fournir
A25: Ce qui est déjà en place côté plateforme
A26: • Le tunnel d'achat complet : compte, récapitulatif, choix du moyen de paiement (Mobile Money, Wave, Djamo, Visa).
A27: • L'enregistrement de la commande, de la transaction et l'ouverture des accès en une seule opération.
A28: • Les six motifs d'échec du prestataire (solde insuffisant, annulation, délai dépassé, réseau opérateur, carte refusée, erreur inconnue), tracés et filtrables dans /admin/transactions.
A29: • Le taux de frais FeexPay paramétrable dans /admin/parametres, utilisé par le calcul des revenus formateurs (CA − frais, puis 30 % formateur / 70 % Big Five).
A31: Ce qui reste à développer une fois les clés reçues
A32: • L'appel réel à l'API FeexPay au lieu de l'échange simulé, et la redirection de l'acheteur.
A33: • L'endpoint public de retour (webhook), vérifié par signature et idempotent — un même paiement notifié deux fois ne doit ouvrir l'accès qu'une fois.
A34: • Le rapprochement quotidien entre les transactions de la plateforme et le relevé du prestataire.
A35: • La recette du tunnel sur l'environnement de test du prestataire, avec les six motifs d'échec réels.
A37: Transmission des clés : les clés de production ne doivent jamais circuler par e-mail en clair. Les déposer directement dans les variables d'environnement du serveur de production, ou les transmettre par un canal chiffré à usage unique.

Sheet Comptes et clés
A1: Comptes prestataires et clés
A2: Ce qui est déjà en service, et ce qui manque. Le détail du paiement est dans l'onglet « Paiement — FeexPay ».
A4: Prestataire / compte | B4: Ce qu'il faut ouvrir ou fournir | C4: Où cela se règle | D4: Statut | E4: Remarque
A5: Supabase (base de données) | B5: Projet hébergé, URL et clé secrète sb_secret_… | C5: SUPABASE_URL, SUPABASE_SECRET_KEY | D5: Fourni — en service | E5: Migrations 01 à 05 appliquées et vérifiées le 02/09
A6: Cloudflare R2 + Worker (vidéo) | B6: Bucket, Worker déployé, secret de signature partagé | C6: VIDEO_BASE_URL, VIDEO_SIGNING_SECRET | D6: Fourni — en service | E6: Vérifié le 02/09 : les démonstrations se lisent depuis le CDN, le cloisonnement des chapitres tient
A7: Envoi d'e-mails transactionnels | B7: Compte Brevo, Resend, Postmark ou SMTP de l'hébergeur + SPF, DKIM, DMARC sur bigfive.ci | C7: NOTIFICATIONS_DRIVER, SMTP_HOST, SMTP_USER, SMTP_PASS, SMTP_EXPEDITEUR | D7: À fournir — bloquant | E7: Débloque réinitialisation, confirmation d'achat, envoi d'attestation, avis d'annulation
A8: Supabase Auth — SMTP personnalisé | B8: Le même compte SMTP, plus un jeton d'accès personnel Supabase | C8: SUPABASE_ACCESS_TOKEN puis npm run auth:configurer, CODE_ADMIN_FOURNISSEUR=supabase-auth | D8: À fournir — bloquant | E8: Sans lui, le code de /admin/login reste écrit dans la sortie du serveur
A9: FeexPay (encaissement) | B9: Voir l'onglet « Paiement — FeexPay » : compte marchand, clés test et production, secret de webhook, URL de retour | C9: Variables à créer : FEEXPAY_SHOP_ID, FEEXPAY_API_KEY, FEEXPAY_MODE, FEEXPAY_WEBHOOK_SECRET | D9: À fournir — bloquant | E9: Aucune variable FeexPay n'existe à ce jour dans la configuration : l'intégration reste entièrement à faire
A10: Zoom (coaching collectif) | B10: Compte Zoom Pro et application « Meeting SDK » | C10: SDK Key et SDK Secret (variables à créer) | D10: À fournir — bloquant | E10: En attendant, l'équipe crée la réunion à la main et transmet le lien
A11: WhatsApp Business (notifications) | B11: Accès Meta direct ou via 360dialog / Twilio / Vonage, numéro vérifié, modèles validés | C11: Identifiants du numéro et du compte, jeton permanent | D11: À fournir | E11: Meta met 1 à 2 semaines à valider les modèles — à lancer tôt
A12: Google Analytics 4 et Search Console | B12: Propriété GA4, conteneur GTM, domaine vérifié | C12: Saisie dans /admin/tracking, écran déjà prêt | D12: À fournir | E12: Débloque les six indicateurs à « — » de /admin/performances
A13: Domaine et hébergement de production | B13: emasterclass.bigfive.ci pointé, certificat HTTPS, variables d'environnement posées | C13: NUXT_PUBLIC_SITE_URL, NUXT_SESSION_PASSWORD | D13: À fournir — bloquant | E13: NUXT_PUBLIC_SITE_URL alimente les canonical, le sitemap et le lien de vérification des attestations

Sheet Conformité SEO
A1: Conformité aux spécifications SEO
A2: Reprise du document « Spécifications SEO développeur » transmis avec l'e-mail de lancement (maquettes/specifications/03_Specifications_SEO.md).
A4: Point de la spéc. | B4: Exigence | C4: Où c'est implémenté | D4: État | E4: Réserve | F4: Verdict recette
A5: §1 | B5: Pages indexables : accueil, programmes, modules publiés, formateurs, devenir formateur, contact, blog | C5: nuxt.config.ts (robots, sitemap) + usePagePrivee() par page | D5: Développé
A6: §2 | B6: Pages non indexables : authentification, tunnel, dashboards, contenus privés | C6: noindex et exclusion du sitemap vérifiés sur le build de production | D6: Développé
A7: §3 | B7: Onglet back-office « Référencement et partage » | C7: app/pages/admin/referencement.vue + server/api/admin/referencement.* | D7: Développé
A8: §3 | B8: Champs éditables par les administrateurs de contenu (mot-clé, Title, description, Open Graph, alt) | C8: Éditeur de module et éditeur d'article, panneau Référencement | D8: Développé
A9: §3 | B9: Champs réservés aux administrateurs supérieurs (slug, indexation, canonical) | C9: Filtrés côté serveur selon le rôle, désactivés côté interface | D9: Développé
A10: §3 | B10: Alerte sur les doublons Title / Meta description | C10: detecterDoublons() dans server/utils/seo.ts, alerte en direct | D10: Développé
A11: §3 | B11: Confirmation avant modification d'une URL publiée | C11: confirmationSlug exigé par l'API, HTTP 428 sinon | D11: Développé
A12: §4 | B12: Valeurs automatiques, jamais de meta keywords | C12: usePageSeo() et resoudreSeo() | D12: Développé
A13: §5 | B13: Statuts brouillon / publié / en préparation | C13: Champ statut, exclusion du sitemap et des listes publiques | D13: Développé
A14: §5 | B14: Redirection 301 au changement de slug | C14: server/middleware/redirections.ts | D14: Développé
A15: §6 | B15: Un seul H1, hiérarchie logique, rendu serveur | C15: Vérifié sur le build de production | D15: Développé
A16: §6 | B16: Carrousel accessible : clavier, pause au survol, glissement tactile | C16: app/components/home/HeroCarousel.vue | D16: Développé
... A18: §8 | B18: Sitemap XML et robots.txt | C18: server/api/__sitemap__/urls.get.ts ; Disallow /formateur/ sans bloquer /formateurs | D18: Développé
A19: §8 | B19: Soumission du sitemap dans la Search Console | C19: À faire une fois le domaine vérifié | D19: Bloqué — prestataire | E19: Demande l'accès Search Console
A20: §9 | B20: Données structurées JSON-LD | C20: nuxt-schema-org (Organization) + useJsonLd() : Course, Person, Article, BreadcrumbList, FAQPage, ItemList | D20: Développé
A21: §9 | B21: Test avec Rich Results Test et Schema Markup Validator | C21: À faire sur l'URL de production | D21: Non développé | E21: Ne peut se faire qu'en ligne
A22: §10 | B22: Images responsives, WebP/AVIF, alt éditable, Open Graph par page | C22: @nuxt/image, alt éditable en back-office, Open Graph par page | D22: Développé | E22: Les visuels définitifs manquent : placeholders rayés
A23: §11 | B23: Contenu identique desktop / mobile / PWA, pas d'URL mobile séparée | C23: Rendu serveur unique | D23: Développé
A24: §11 | B24: Core Web Vitals suivis | C24: Mesure à mettre en place après la mise en production | D24: Non développé | E24: Demande GA4 et le domaine de production
A25: §12 | B25: Search Console et GA4 connectés, suivi des événements clés | C25: /admin/tracking prêt à recevoir les identifiants | D25: Bloqué — prestataire | E25: Six indicateurs affichent « — » en attendant
A26: §13 | B26: Permissions : contenu vs administrateur supérieur | C26: exigerAdmin(event, superieur), exigerFormateur(event), 17 sections | D26: Développé
A27: §14 | B27: Hors périmètre : pas de meta keywords, sitemap/canonical/redirections automatiques | C27: Respecté | D27: Développé

Sheet Couverture e-mail
A1: Couverture de l'e-mail de lancement
A2: Les points transmis au démarrage du développement, et leur traitement.
A4: Point de l'e-mail | B4: Demande du client | C4: Ce qui a été fait | D4: État | E4: Ce qui reste ouvert
A5: 1 | B5: Arborescence et flux de navigation (planche E) | C5: Les 6 parcours sont implémentés : achat, coaching collectif, coaching privé, mise en ligne d'un module, publication d'un article, candidature → formateur | D5: Traité | E5: Parcours 01 et 02 dépendent de FeexPay et de Zoom pour être complets en production
A6: 2 | B6: Handoff de la maquette | C6: Planches A à D reproduites, jetons de couleur repris (violet #80368D, bleu #29358B), motif et logo intégrés | D6: Traité | E6: 5 écarts assumés documentés dans le README : titres de 8 modules, répartition formateurs, visuels, textes des modules, responsive traité en points de rupture
A7: 3 | B7: Numéro WhatsApp +225 05 75 15 21 44 | C7: Centralisé dans shared/utils/contact.ts, lien https://wa.me/2250575152144 ; utilisé par le bouton flottant, le pied de page, l'accueil, la FAQ, les fiches modules et formateurs, le partage d'articles | D7: Traité | E7: L'envoi automatique de messages WhatsApp demande encore un compte WhatsApp Business
A8: 4 | B8: Attestation de participation | C8: Squelette repris (variables dynamiques), visuel de référence reproduit, numérotation EMBF-…, QR de vérification, export PDF A4 paysage | D8: Traité — sauf la signature | E8: La griffe de la direction en PNG à fond transparent n'a pas été fournie ; l'envoi par e-mail attend le prestataire
A9: 5 | B9: Spécifications SEO | C9: Points §1 à §14 traités ; voir l'onglet « Conformité SEO » pour le détail ligne à ligne | D9: Traité | E9: Les points de mesure (§8 soumission, §12 GA4/Search Console) attendent les accès
A10: 5 bis | B10: Onglet référencement dans l'interface admin | C10: /admin/referencement : pages indexables filtrables par type, édition du SEO, droits séparés contenu / supérieur | D10: Traité
A11: 5 ter | B11: Section Blog | C11: /blog, /blog/[slug], /admin/blog et éditeur d'article avec panneau de référencement | D11: Traité | E11: 5 articles de démonstration ; le contenu éditorial définitif reste à fournir
A12: 6 | B12: Typographies Jost et Mulish | C12: Jost 300/400/500/600 pour les titres, Mulish 400/600/700/800 pour les textes, auto-hébergées via @nuxt/fonts ; plus aucune trace de Century Gothic ni de Nicky Sans | D12: Traité
A14: Documents de référence reçus : arborescence des parcours (planche E), handoff de la maquette (planches A à D), squelette et visuel de l'attestation, spécifications SEO. Tous ont été exploités ; les planches A à D et le modèle d'attestation sont archivés dans maquettes/ du dépôt.
